Workbook

Sheet Instructions
B1: MAGCS Inflight Catering – Skytrax 2026 Readiness Checklist & Monitor
B2: Built from: Skytrax Agenda 2026 (22 legs, 3 itineraries) and STD UPLIFT INFORMATION.xlsx (aircraft data: Update as @20JUL26).
B4: How to use this workbook
B5: Purpose: monitor MAGCS inflight-catering readiness for all 22 legs of the Skytrax Agenda 2026 audit itineraries, with three checkpoints per flight calculated from scheduled departure (STD) in the correct station time zone: T-7D, T-24H and T-12H. T-12H is recorded in two parts: the preparation check at the caterer (T-12H PREP) and the physical on-board uplift confirmation before departure (UPLIFT), so dashboards show four columns.
B6: Sheets
B7: • Dashboard – checkpoint completion, overdue actions, outstanding discrepancies and readiness per flight.
B8: • Flights – the 22 legs as scheduled. Enter Tail/Reg, Caterer and Flight PIC (yellow). Due times: T-7D, T-24H, T-12H prep and uplift (= STD).
B9: • Checks – one row per check per flight. THE ONLY PLACE TO RECORD RESULTS (yellow columns S–AE).
B10: • Documents – galley loading diagram and menu checklist per flight (doc no, revision, date, attachment). ISOP Register – ISOP revisions communicated to caterers.
B11: • Requirements – uplift requirements derived from STD UPLIFT INFORMATION.xlsx per flight, with source cell for each.
B12: • Settings – as-of time, PC clock offset, validity windows, station time-zone table.
B13: • P01–P22 – printable pack per flight (formula views of Checks, A4 landscape). Page 1 is a cover sheet with the flight's due times, readiness, the attachments register (A1 galley loading diagram, A2 menu checklist – staple behind, flagged OUTSTANDING until on file) and sign-off; the checklist starts on page 2. Print one flight's sheet on its own so page numbers run per flight.
... B55: Blue text = value transcribed from a reference (schedule, time-zone table, reference quantity)

Sheet Dashboard
B1: MAGCS Inflight Catering – Skytrax 2026 Readiness Dashboard
B2: As of (UTC) | D2: =AsOfUTC -> 46294.537 | F2: As of (MYT) | H2: =AsOfUTC+8/24 -> 46294.871 | J2: =IF(Settings!$B$4<>"","Settings B4 (override) is set → as-of time is fixed","Settings B4 (override) blank → live clock (recalculate to refresh)")&"; effective as-of shown in Settings B6." -> Settings B4 (override) blank → live clock (recalculate to refresh); effective as-of shown in Settings B6.
B4: Key indicators
B5: Flights | D5: Flights READY | F5: Overall completion | H5: Overdue actions | J5: Open discrepancies | L5: Docs outstanding | N5: Clarifications open | P5: Invalid entries
B6: =COUNTA(Flights!$A$5:$A$26) -> 22 | D6: =COUNTIF(Flights!$AT$5:$AT$26,"READY") -> 0 | F6: =IF(SUM(Checks!$AI$5:$AI$748)=0,"n/a",SUM(Checks!$AJ$5:$AJ$748)/SUM(Checks!$AI$5:$AI$748)) -> 0 | H6: =SUM(Checks!$AK$5:$AK$748) -> 0 | J6: =SUM(Checks!$AL$5:$AL$748) -> 0 | L6: =SUM(Flights!$AR$5:$AR$26) -> 44 | N6: =SUM(Flights!$AS$5:$AS$26) -> 33 | P6: =SUM(Checks!$AM$5:$AM$748) -> 0
B7: legs on the agenda | D7: ="of "&COUNTA(Flights!$A$5:$A$26)&" flights" -> of 22 flights | F7: =SUM(Checks!$AJ$5:$AJ$748)&" of "&SUM(Checks!$AI$5:$AI$748)&" checks" -> 0 of 724 checks | H7: past due, not complete | J7: fail, qty variance or CA open | L7: GLD + menu checklist | N7: awaiting reference answer | P7: entries failing validation rules
B9: Checkpoint summary
B10: Checkpoint | D10: In scope | F10: Complete | H10: N/A (justified + rule) | I10: Open | J10: Overdue | L10: Completion | N10: What is checked
B11: T-7D | D11: =SUMIFS(Checks!$AI$5:$AI$748,Checks!$G$5:$G$748,"T-7D") -> 184 | F11: =SUMIFS(Checks!$AJ$5:$AJ$748,Checks!$G$5:$G$748,"T-7D") -> 0 | H11: =COUNTIFS(Checks!$G$5:$G$748,"T-7D",Checks!$AH$5:$AH$748,"N/A – JUSTIFIED*")+COUNTIFS(Checks!$G$5:$G$748,"T-7D",Checks!$AH$5:$AH$748,"N/A – RULE*") -> 20 | I11: =D11-F11 -> 184 | J11: =SUMIFS(Checks!$AK$5:$AK$748,Checks!$G$5:$G$748,"T-7D") -> 0 | L11: =IF(D11=0,"n/a",F11/D11) -> 0 | N11: Preparation checks due 7 days before STD
B12: T-24H | D12: =SUMIFS(Checks!$AI$5:$AI$748,Checks!$G$5:$G$748,"T-24H") -> 22 | F12: =SUMIFS(Checks!$AJ$5:$AJ$748,Checks!$G$5:$G$748,"T-24H") -> 0 | H12: =COUNTIFS(Checks!$G$5:$G$748,"T-24H",Checks!$AH$5:$AH$748,"N/A – JUSTIFIED*")+COUNTIFS(Checks!$G$5:$G$748,"T-24H",Checks!$AH$5:$AH$748,"N/A – RULE*") -> 0 | I12: =D12-F12 -> 22 | J12: =SUMIFS(Checks!$AK$5:$AK$748,Checks!$G$5:$G$748,"T-24H") -> 0 | L12: =IF(D12=0,"n/a",F12/D12) -> 0 | N12: Preparation checks due 24 hours before STD
B13: T-12H prep | D13: =SUMIFS(Checks!$AI$5:$AI$748,Checks!$G$5:$G$748,"T-12H PREP") -> 311 | F13: =SUMIFS(Checks!$AJ$5:$AJ$748,Checks!$G$5:$G$748,"T-12H PREP") -> 0 | H13: =COUNTIFS(Checks!$G$5:$G$748,"T-12H PREP",Checks!$AH$5:$AH$748,"N/A – JUSTIFIED*")+COUNTIFS(Checks!$G$5:$G$748,"T-12H PREP",Checks!$AH$5:$AH$748,"N/A – RULE*") -> 0 | I13: =D13-F13 -> 311 | J13: =SUMIFS(Checks!$AK$5:$AK$748,Checks!$G$5:$G$748,"T-12H PREP") -> 0 | L13: =IF(D13=0,"n/a",F13/D13) -> 0 | N13: Preparation checks due 12 hours before STD
B14: Uplift | D14: =SUMIFS(Checks!$AI$5:$AI$748,Checks!$G$5:$G$748,"UPLIFT") -> 207 | F14: =SUMIFS(Checks!$AJ$5:$AJ$748,Checks!$G$5:$G$748,"UPLIFT") -> 0 | H14: =COUNTIFS(Checks!$G$5:$G$748,"UPLIFT",Checks!$AH$5:$AH$748,"N/A – JUSTIFIED*")+COUNTIFS(Checks!$G$5:$G$748,"UPLIFT",Checks!$AH$5:$AH$748,"N/A – RULE*") -> 0 | I14: =D14-F14 -> 207 | J14: =SUMIFS(Checks!$AK$5:$AK$748,Checks!$G$5:$G$748,"UPLIFT") -> 0 | L14: =IF(D14=0,"n/a",F14/D14) -> 0 | N14: Physical uplift / on-board confirmation, due at STD
B15: All | D15: =SUM(D11:D14) -> 724 | F15: =SUM(F11:F14) -> 0 | H15: =SUM(H11:H14) -> 20 | I15: =SUM(I11:I14) -> 724 | J15: =SUM(J11:J14) -> 0 | L15: =IF(D15=0,"n/a",F15/D15) -> 0 | N15: Open = in scope − complete (includes overdue).
B17: How the figures are calculated
B18: Blank checks | E18: A check line with no Status / completion entry never counts as complete. It stays OPEN until its due time, then becomes OVERDUE.
B19: N/A | E19: N/A only removes a check from the denominator when it is either rule-based (applicability “N/A – rule”, e.g. fleet-specific items) or JUSTIFIED: Status N/A with a written N/A justification AND a named verifier. An unjustified or unverified N/A is flagged INVALID and still counts as open.
B20: Complete | E20: Status Pass or Pass after CA, with a completion time, evidence ref and verifier; plus the batch ID on T-24H lines and expected + actual quantity on quantity lines. A quantity variance is only accepted as Pass after CA with the CA status Closed. GLD / menu-checklist lines also need the document ON FILE (Documents sheet). The completion time must not be in the future or before the valid window, and uplift lines can only be completed within the uplift window before STD (Settings B7). Anything else is OPEN, OVERDUE or INVALID.
B21: Discrepancy | E21: An in-scope check is an open discrepancy when its Status is Fail, OR its CA status is Open, OR its quantity variance is not zero (unless Status is Pass after CA). It clears once the corrective action is recorded and closed.
B22: READY | E22: A flight is READY only when every in-scope check at all four checkpoints is complete – including the physical uplift confirmation – with zero open discrepancies, the GLD and menu checklist on file (Documents sheet) and no invalid entries. PREP DONE – AWAITING UPLIFT means all preparation checks are complete but the physical uplift is not yet confirmed.
B23: Lists | E23: The overdue and discrepancy pages list the first 18 / 18 lines in Checks order. Long text there is shortened with “…” – the full text is on the Checks sheet.
B24: Time basis | E24: Due times are computed in UTC from STD and shown in local time at the check station. As-of time is Settings B6: the override in B4 if set, otherwise the PC clock adjusted by the offset in B5.
B26: Per-flight readiness | L26: ="As of "&TEXT(AsOfUTC+8/24,"dd-mmm-yy hh:mm")&" MYT" -> As of 29-Sep-26 20:53 MYT
B27: Itin | C27: Flight | D27: Date | E27: Sector | F27: Cls | G27: Fleet | H27: STD local | I27: T-7D | J27: T-24H | K27: T-12H prep | L27: Uplift | M27: Overall | N27: Over-due | O27: Dis-crep. | P27: Docs out | Q27: Clarif. open | R27: Readiness
B28: =IF(Flights!$B$5="","",Flights!$B$5) -> 1 | C28: =IF(Flights!$F$5="","",Flights!$F$5) -> MH0001 | D28: =IF(Flights!$D$5="","",Flights!$D$5) -> 46303 | E28: =IF(Flights!$G$5="","",Flights!$G$5&"-"&Flights!$H$5) -> LHR-KUL | F28: =IF(Flights!$K$5="","",Flights!$K$5) -> EY | G28: =IF(Flights!$L$5="","",Flights!$L$5) -> A350 | H28: =IF(Flights!$I$5="","",Flights!$I$5) -> 46303.899 | I28: =IF(Flights!$AJ$5="","",Flights!$AJ$5) -> 0 | J28: =IF(Flights!$AK$5="","",Flights!$AK$5) -> 0 | K28: =IF(Flights!$AL$5="","",Flights!$AL$5) -> 0 | L28: =IF(Flights!$AM$5="","",Flights!$AM$5) -> 0 | M28: =IF(Flights!$AN$5="","",Flights!$AN$5) -> 0 | N28: =IF(Flights!$AP$5="","",Flights!$AP$5) -> 0 | O28: =IF(Flights!$AQ$5="","",Flights!$AQ$5) -> 0 | P28: =IF(Flights!$AR$5="","",Flights!$AR$5) -> 2 | Q28: =IF(Flights!$AS$5="","",Flights!$AS$5) -> 2 | R28: =IF(Flights!$AT$5="","",Flights!$AT$5) -> NOT READY – DOCUMENTS
B29: =IF(Flights!$B$6="","",Flights!$B$6) -> 1 | C29: =IF(Flights!$F$6="","",Flights!$F$6) -> MH0727 | D29: =IF(Flights!$D$6="","",Flights!$D$6) -> 46304 | E29: =IF(Flights!$G$6="","",Flights!$G$6&"-"&Flights!$H$6) -> KUL-CGK | F29: =IF(Flights!$K$6="","",Flights!$K$6) -> BC | G29: =IF(Flights!$L$6="","",Flights!$L$6) -> B738MAX | H29: =IF(Flights!$I$6="","",Flights!$I$6) -> 46304.91 | I29: =IF(Flights!$AJ$6="","",Flights!$AJ$6) -> 0 | J29: =IF(Flights!$AK$6="","",Flights!$AK$6) -> 0 | K29: =IF(Flights!$AL$6="","",Flights!$AL$6) -> 0 | L29: =IF(Flights!$AM$6="","",Flights!$AM$6) -> 0 | M29: =IF(Flights!$AN$6="","",Flights!$AN$6) -> 0 | N29: =IF(Flights!$AP$6="","",Flights!$AP$6) -> 0 | O29: =IF(Flights!$AQ$6="","",Flights!$AQ$6) -> 0 | P29: =IF(Flights!$AR$6="","",Flights!$AR$6) -> 2 | Q29: =IF(Flights!$AS$6="","",Flights!$AS$6) -> 2 | R29: =IF(Flights!$AT$6="","",Flights!$AT$6) -> NOT READY – DOCUMENTS
B30: =IF(Flights!$B$7="","",Flights!$B$7) -> 1 | C30: =IF(Flights!$F$7="","",Flights!$F$7) -> MH0720 | D30: =IF(Flights!$D$7="","",Flights!$D$7) -> 46305 | E30: =IF(Flights!$G$7="","",Flights!$G$7&"-"&Flights!$H$7) -> CGK-KUL | F30: =IF(Flights!$K$7="","",Flights!$K$7) -> EY | G30: =IF(Flights!$L$7="","",Flights!$L$7) -> A333 | H30: =IF(Flights!$I$7="","",Flights!$I$7) -> 46305.67 | I30: =IF(Flights!$AJ$7="","",Flights!$AJ$7) -> 0 | J30: =IF(Flights!$AK$7="","",Flights!$AK$7) -> 0 | K30: =IF(Flights!$AL$7="","",Flights!$AL$7) -> 0 | L30: =IF(Flights!$AM$7="","",Flights!$AM$7) -> 0 | M30: =IF(Flights!$AN$7="","",Flights!$AN$7) -> 0 | N30: =IF(Flights!$AP$7="","",Flights!$AP$7) -> 0 | O30: =IF(Flights!$AQ$7="","",Flights!$AQ$7) -> 0 | P30: =IF(Flights!$AR$7="","",Flights!$AR$7) -> 2 | Q30: =IF(Flights!$AS$7="","",Flights!$AS$7) -> 0 | R30: =IF(Flights!$AT$7="","",Flights!$AT$7) -> NOT READY – DOCUMENTS
B31: =IF(Flights!$B$8="","",Flights!$B$8) -> 1 | C31: =IF(Flights!$F$8="","",Flights!$F$8) -> MH0088 | D31: =IF(Flights!$D$8="","",Flights!$D$8) -> 46305 | E31: =IF(Flights!$G$8="","",Flights!$G$8&"-"&Flights!$H$8) -> KUL-NRT | F31: =IF(Flights!$K$8="","",Flights!$K$8) -> BC | G31: =IF(Flights!$L$8="","",Flights!$L$8) -> A350 | H31: =IF(Flights!$I$8="","",Flights!$I$8) -> 46305.979 | I31: =IF(Flights!$AJ$8="","",Flights!$AJ$8) -> 0 | J31: =IF(Flights!$AK$8="","",Flights!$AK$8) -> 0 | K31: =IF(Flights!$AL$8="","",Flights!$AL$8) -> 0 | L31: =IF(Flights!$AM$8="","",Flights!$AM$8) -> 0 | M31: =IF(Flights!$AN$8="","",Flights!$AN$8) -> 0 | N31: =IF(Flights!$AP$8="","",Flights!$AP$8) -> 0 | O31: =IF(Flights!$AQ$8="","",Flights!$AQ$8) -> 0 | P31: =IF(Flights!$AR$8="","",Flights!$AR$8) -> 2 | Q31: =IF(Flights!$AS$8="","",Flights!$AS$8) -> 1 | R31: =IF(Flights!$AT$8="","",Flights!$AT$8) -> NOT READY – DOCUMENTS
B32: =IF(Flights!$B$9="","",Flights!$B$9) -> 1 | C32: =IF(Flights!$F$9="","",Flights!$F$9) -> MH0089 | D32: =IF(Flights!$D$9="","",Flights!$D$9) -> 46310 | E32: =IF(Flights!$G$9="","",Flights!$G$9&"-"&Flights!$H$9) -> NRT-KUL | F32: =IF(Flights!$K$9="","",Flights!$K$9) -> EY | G32: =IF(Flights!$L$9="","",Flights!$L$9) -> A350 | H32: =IF(Flights!$I$9="","",Flights!$I$9) -> 46310.42 | I32: =IF(Flights!$AJ$9="","",Flights!$AJ$9) -> 0 | J32: =IF(Flights!$AK$9="","",Flights!$AK$9) -> 0 | K32: =IF(Flights!$AL$9="","",Flights!$AL$9) -> 0 | L32: =IF(Flights!$AM$9="","",Flights!$AM$9) -> 0 | M32: =IF(Flights!$AN$9="","",Flights!$AN$9) -> 0 | N32: =IF(Flights!$AP$9="","",Flights!$AP$9) -> 0 | O32: =IF(Flights!$AQ$9="","",Flights!$AQ$9) -> 0 | P32: =IF(Flights!$AR$9="","",Flights!$AR$9) -> 2 | Q32: =IF(Flights!$AS$9="","",Flights!$AS$9) -> 4 | R32: =IF(Flights!$AT$9="","",Flights!$AT$9) -> NOT READY – DOCUMENTS
B33: =IF(Flights!$B$10="","",Flights!$B$10) -> 1 | C33: =IF(Flights!$F$10="","",Flights!$F$10) -> MH0002 | D33: =IF(Flights!$D$10="","",Flights!$D$10) -> 46310 | E33: =IF(Flights!$G$10="","",Flights!$G$10&"-"&Flights!$H$10) -> KUL-LHR | F33: =IF(Flights!$K$10="","",Flights!$K$10) -> BC | G33: =IF(Flights!$L$10="","",Flights!$L$10) -> A350 | H33: =IF(Flights!$I$10="","",Flights!$I$10) -> 46310.972 | I33: =IF(Flights!$AJ$10="","",Flights!$AJ$10) -> 0 | J33: =IF(Flights!$AK$10="","",Flights!$AK$10) -> 0 | K33: =IF(Flights!$AL$10="","",Flights!$AL$10) -> 0 | L33: =IF(Flights!$AM$10="","",Flights!$AM$10) -> 0 | M33: =IF(Flights!$AN$10="","",Flights!$AN$10) -> 0 | N33: =IF(Flights!$AP$10="","",Flights!$AP$10) -> 0 | O33: =IF(Flights!$AQ$10="","",Flights!$AQ$10) -> 0 | P33: =IF(Flights!$AR$10="","",Flights!$AR$10) -> 2 | Q33: =IF(Flights!$AS$10="","",Flights!$AS$10) -> 2 | R33: =IF(Flights!$AT$10="","",Flights!$AT$10) -> NOT READY – DOCUMENTS
B34: =IF(Flights!$B$11="","",Flights!$B$11) -> 2 | C34: =IF(Flights!$F$11="","",Flights!$F$11) -> MH0003 | D34: =IF(Flights!$D$11="","",Flights!$D$11) -> 46304 | E34: =IF(Flights!$G$11="","",Flights!$G$11&"-"&Flights!$H$11) -> LHR-KUL | F34: =IF(Flights!$K$11="","",Flights!$K$11) -> BC | G34: =IF(Flights!$L$11="","",Flights!$L$11) -> A350 | H34: =IF(Flights!$I$11="","",Flights!$I$11) -> 46304.458 | I34: =IF(Flights!$AJ$11="","",Flights!$AJ$11) -> 0 | J34: =IF(Flights!$AK$11="","",Flights!$AK$11) -> 0 | K34: =IF(Flights!$AL$11="","",Flights!$AL$11) -> 0 | L34: =IF(Flights!$AM$11="","",Flights!$AM$11) -> 0 | M34: =IF(Flights!$AN$11="","",Flights!$AN$11) -> 0 | N34: =IF(Flights!$AP$11="","",Flights!$AP$11) -> 0 | O34: =IF(Flights!$AQ$11="","",Flights!$AQ$11) -> 0 | P34: =IF(Flights!$AR$11="","",Flights!$AR$11) -> 2 | Q34: =IF(Flights!$AS$11="","",Flights!$AS$11) -> 3 | R34: =IF(Flights!$AT$11="","",Flights!$AT$11) -> NOT READY – DOCUMENTS
B35: =IF(Flights!$B$12="","",Flights!$B$12) -> 2 | C35: =IF(Flights!$F$12="","",Flights!$F$12) -> MH0752 | D35: =IF(Flights!$D$12="","",Flights!$D$12) -> 46305 | E35: =IF(Flights!$G$12="","",Flights!$G$12&"-"&Flights!$H$12) -> KUL-HAN | F35: =IF(Flights!$K$12="","",Flights!$K$12) -> EY | G35: =IF(Flights!$L$12="","",Flights!$L$12) -> B738MAX | H35: =IF(Flights!$I$12="","",Flights!$I$12) -> 46305.399 | I35: =IF(Flights!$AJ$12="","",Flights!$AJ$12) -> 0 | J35: =IF(Flights!$AK$12="","",Flights!$AK$12) -> 0 | K35: =IF(Flights!$AL$12="","",Flights!$AL$12) -> 0 | L35: =IF(Flights!$AM$12="","",Flights!$AM$12) -> 0 | M35: =IF(Flights!$AN$12="","",Flights!$AN$12) -> 0 | N35: =IF(Flights!$AP$12="","",Flights!$AP$12) -> 0 | O35: =IF(Flights!$AQ$12="","",Flights!$AQ$12) -> 0 | P35: =IF(Flights!$AR$12="","",Flights!$AR$12) -> 2 | Q35: =IF(Flights!$AS$12="","",Flights!$AS$12) -> 0 | R35: =IF(Flights!$AT$12="","",Flights!$AT$12) -> NOT READY – DOCUMENTS
B36: =IF(Flights!$B$13="","",Flights!$B$13) -> 2 | C36: =IF(Flights!$F$13="","",Flights!$F$13) -> MH0753 | D36: =IF(Flights!$D$13="","",Flights!$D$13) -> 46306 | E36: =IF(Flights!$G$13="","",Flights!$G$13&"-"&Flights!$H$13) -> HAN-KUL | F36: =IF(Flights!$K$13="","",Flights!$K$13) -> BC | G36: =IF(Flights!$L$13="","",Flights!$L$13) -> B738MAX | H36: =IF(Flights!$I$13="","",Flights!$I$13) -> 46306.545 | I36: =IF(Flights!$AJ$13="","",Flights!$AJ$13) -> 0 | J36: =IF(Flights!$AK$13="","",Flights!$AK$13) -> 0 | K36: =IF(Flights!$AL$13="","",Flights!$AL$13) -> 0 | L36: =IF(Flights!$AM$13="","",Flights!$AM$13) -> 0 | M36: =IF(Flights!$AN$13="","",Flights!$AN$13) -> 0 | N36: =IF(Flights!$AP$13="","",Flights!$AP$13) -> 0 | O36: =IF(Flights!$AQ$13="","",Flights!$AQ$13) -> 0 | P36: =IF(Flights!$AR$13="","",Flights!$AR$13) -> 2 | Q36: =IF(Flights!$AS$13="","",Flights!$AS$13) -> 2 | R36: =IF(Flights!$AT$13="","",Flights!$AT$13) -> NOT READY – DOCUMENTS
B37: =IF(Flights!$B$14="","",Flights!$B$14) -> 2 | C37: =IF(Flights!$F$14="","",Flights!$F$14) -> MH1140 | D37: =IF(Flights!$D$14="","",Flights!$D$14) -> 46307 | E37: =IF(Flights!$G$14="","",Flights!$G$14&"-"&Flights!$H$14) -> KUL-PEN | F37: =IF(Flights!$K$14="","",Flights!$K$14) -> BC | G37: =IF(Flights!$L$14="","",Flights!$L$14) -> B738MAX | H37: =IF(Flights!$I$14="","",Flights!$I$14) -> 46307.49 | I37: =IF(Flights!$AJ$14="","",Flights!$AJ$14) -> 0 | J37: =IF(Flights!$AK$14="","",Flights!$AK$14) -> 0 | K37: =IF(Flights!$AL$14="","",Flights!$AL$14) -> 0 | L37: =IF(Flights!$AM$14="","",Flights!$AM$14) -> 0 | M37: =IF(Flights!$AN$14="","",Flights!$AN$14) -> 0 | N37: =IF(Flights!$AP$14="","",Flights!$AP$14) -> 0 | O37: =IF(Flights!$AQ$14="","",Flights!$AQ$14) -> 0 | P37: =IF(Flights!$AR$14="","",Flights!$AR$14) -> 2 | Q37: =IF(Flights!$AS$14="","",Flights!$AS$14) -> 0 | R37: =IF(Flights!$AT$14="","",Flights!$AT$14) -> NOT READY – DOCUMENTS
B38: =IF(Flights!$B$15="","",Flights!$B$15) -> 2 | C38: =IF(Flights!$F$15="","",Flights!$F$15) -> MH1149 | D38: =IF(Flights!$D$15="","",Flights!$D$15) -> 46307 | E38: =IF(Flights!$G$15="","",Flights!$G$15&"-"&Flights!$H$15) -> PEN-KUL | F38: =IF(Flights!$K$15="","",Flights!$K$15) -> EY | G38: =IF(Flights!$L$15="","",Flights!$L$15) -> B738MAX | H38: =IF(Flights!$I$15="","",Flights!$I$15) -> 46307.66 | I38: =IF(Flights!$AJ$15="","",Flights!$AJ$15) -> 0 | J38: =IF(Flights!$AK$15="","",Flights!$AK$15) -> 0 | K38: =IF(Flights!$AL$15="","",Flights!$AL$15) -> 0 | L38: =IF(Flights!$AM$15="","",Flights!$AM$15) -> 0 | M38: =IF(Flights!$AN$15="","",Flights!$AN$15) -> 0 | N38: =IF(Flights!$AP$15="","",Flights!$AP$15) -> 0 | O38: =IF(Flights!$AQ$15="","",Flights!$AQ$15) -> 0 | P38: =IF(Flights!$AR$15="","",Flights!$AR$15) -> 2 | Q38: =IF(Flights!$AS$15="","",Flights!$AS$15) -> 1 | R38: =IF(Flights!$AT$15="","",Flights!$AT$15) -> NOT READY – DOCUMENTS
B39: =IF(Flights!$B$16="","",Flights!$B$16) -> 2 | C39: =IF(Flights!$F$16="","",Flights!$F$16) -> MH0139 | D39: =IF(Flights!$D$16="","",Flights!$D$16) -> 46307 | E39: =IF(Flights!$G$16="","",Flights!$G$16&"-"&Flights!$H$16) -> KUL-ADL | F39: =IF(Flights!$K$16="","",Flights!$K$16) -> BC | G39: =IF(Flights!$L$16="","",Flights!$L$16) -> A339 | H39: =IF(Flights!$I$16="","",Flights!$I$16) -> 46307.934 | I39: =IF(Flights!$AJ$16="","",Flights!$AJ$16) -> 0 | J39: =IF(Flights!$AK$16="","",Flights!$AK$16) -> 0 | K39: =IF(Flights!$AL$16="","",Flights!$AL$16) -> 0 | L39: =IF(Flights!$AM$16="","",Flights!$AM$16) -> 0 | M39: =IF(Flights!$AN$16="","",Flights!$AN$16) -> 0 | N39: =IF(Flights!$AP$16="","",Flights!$AP$16) -> 0 | O39: =IF(Flights!$AQ$16="","",Flights!$AQ$16) -> 0 | P39: =IF(Flights!$AR$16="","",Flights!$AR$16) -> 2 | Q39: =IF(Flights!$AS$16="","",Flights!$AS$16) -> 0 | R39: =IF(Flights!$AT$16="","",Flights!$AT$16) -> NOT READY – DOCUMENTS
B40: =IF(Flights!$B$17="","",Flights!$B$17) -> 2 | C40: =IF(Flights!$F$17="","",Flights!$F$17) -> MH0138 | D40: =IF(Flights!$D$17="","",Flights!$D$17) -> 46309 | E40: =IF(Flights!$G$17="","",Flights!$G$17&"-"&Flights!$H$17) -> ADL-KUL | F40: =IF(Flights!$K$17="","",Flights!$K$17) -> EY | G40: =IF(Flights!$L$17="","",Flights!$L$17) -> A339 | H40: =IF(Flights!$I$17="","",Flights!$I$17) -> 46309.448 | I40: =IF(Flights!$AJ$17="","",Flights!$AJ$17) -> 0 | J40: =IF(Flights!$AK$17="","",Flights!$AK$17) -> 0 | K40: =IF(Flights!$AL$17="","",Flights!$AL$17) -> 0 | L40: =IF(Flights!$AM$17="","",Flights!$AM$17) -> 0 | M40: =IF(Flights!$AN$17="","",Flights!$AN$17) -> 0 | N40: =IF(Flights!$AP$17="","",Flights!$AP$17) -> 0 | O40: =IF(Flights!$AQ$17="","",Flights!$AQ$17) -> 0 | P40: =IF(Flights!$AR$17="","",Flights!$AR$17) -> 2 | Q40: =IF(Flights!$AS$17="","",Flights!$AS$17) -> 3 | R40: =IF(Flights!$AT$17="","",Flights!$AT$17) -> NOT READY – DOCUMENTS
B41: =IF(Flights!$B$18="","",Flights!$B$18) -> 2 | C41: =IF(Flights!$F$18="","",Flights!$F$18) -> MH0004 | D41: =IF(Flights!$D$18="","",Flights!$D$18) -> 46310 | E41: =IF(Flights!$G$18="","",Flights!$G$18&"-"&Flights!$H$18) -> KUL-LHR | F41: =IF(Flights!$K$18="","",Flights!$K$18) -> EY | G41: =IF(Flights!$L$18="","",Flights!$L$18) -> A350 | H41: =IF(Flights!$I$18="","",Flights!$I$18) -> 46310.41 | I41: =IF(Flights!$AJ$18="","",Flights!$AJ$18) -> 0 | J41: =IF(Flights!$AK$18="","",Flights!$AK$18) -> 0 | K41: =IF(Flights!$AL$18="","",Flights!$AL$18) -> 0 | L41: =IF(Flights!$AM$18="","",Flights!$AM$18) -> 0 | M41: =IF(Flights!$AN$18="","",Flights!$AN$18) -> 0 | N41: =IF(Flights!$AP$18="","",Flights!$AP$18) -> 0 | O41: =IF(Flights!$AQ$18="","",Flights!$AQ$18) -> 0 | P41: =IF(Flights!$AR$18="","",Flights!$AR$18) -> 2 | Q41: =IF(Flights!$AS$18="","",Flights!$AS$18) -> 2 | R41: =IF(Flights!$AT$18="","",Flights!$AT$18) -> NOT READY – DOCUMENTS
B42: =IF(Flights!$B$19="","",Flights!$B$19) -> 3 | C42: =IF(Flights!$F$19="","",Flights!$F$19) -> MH0003 | D42: =IF(Flights!$D$19="","",Flights!$D$19) -> 46320 | E42: =IF(Flights!$G$19="","",Flights!$G$19&"-"&Flights!$H$19) -> LHR-KUL | F42: =IF(Flights!$K$19="","",Flights!$K$19) -> EY | G42: =IF(Flights!$L$19="","",Flights!$L$19) -> A350 | H42: =IF(Flights!$I$19="","",Flights!$I$19) -> 46320.458 | I42: =IF(Flights!$AJ$19="","",Flights!$AJ$19) -> 0 | J42: =IF(Flights!$AK$19="","",Flights!$AK$19) -> 0 | K42: =IF(Flights!$AL$19="","",Flights!$AL$19) -> 0 | L42: =IF(Flights!$AM$19="","",Flights!$AM$19) -> 0 | M42: =IF(Flights!$AN$19="","",Flights!$AN$19) -> 0 | N42: =IF(Flights!$AP$19="","",Flights!$AP$19) -> 0 | O42: =IF(Flights!$AQ$19="","",Flights!$AQ$19) -> 0 | P42: =IF(Flights!$AR$19="","",Flights!$AR$19) -> 2 | Q42: =IF(Flights!$AS$19="","",Flights!$AS$19) -> 2 | R42: =IF(Flights!$AT$19="","",Flights!$AT$19) -> NOT READY – DOCUMENTS
B43: =IF(Flights!$B$20="","",Flights!$B$20) -> 3 | C43: =IF(Flights!$F$20="","",Flights!$F$20) -> MH0072 | D43: =IF(Flights!$D$20="","",Flights!$D$20) -> 46321 | E43: =IF(Flights!$G$20="","",Flights!$G$20&"-"&Flights!$H$20) -> KUL-HKG | F43: =IF(Flights!$K$20="","",Flights!$K$20) -> EY | G43: =IF(Flights!$L$20="","",Flights!$L$20) -> B738MAX | H43: =IF(Flights!$I$20="","",Flights!$I$20) -> 46321.382 | I43: =IF(Flights!$AJ$20="","",Flights!$AJ$20) -> 0 | J43: =IF(Flights!$AK$20="","",Flights!$AK$20) -> 0 | K43: =IF(Flights!$AL$20="","",Flights!$AL$20) -> 0 | L43: =IF(Flights!$AM$20="","",Flights!$AM$20) -> 0 | M43: =IF(Flights!$AN$20="","",Flights!$AN$20) -> 0 | N43: =IF(Flights!$AP$20="","",Flights!$AP$20) -> 0 | O43: =IF(Flights!$AQ$20="","",Flights!$AQ$20) -> 0 | P43: =IF(Flights!$AR$20="","",Flights!$AR$20) -> 2 | Q43: =IF(Flights!$AS$20="","",Flights!$AS$20) -> 1 | R43: =IF(Flights!$AT$20="","",Flights!$AT$20) -> NOT READY – DOCUMENTS
B44: =IF(Flights!$B$21="","",Flights!$B$21) -> 3 | C44: =IF(Flights!$F$21="","",Flights!$F$21) -> MH0073 | D44: =IF(Flights!$D$21="","",Flights!$D$21) -> 46322 | E44: =IF(Flights!$G$21="","",Flights!$G$21&"-"&Flights!$H$21) -> HKG-KUL | F44: =IF(Flights!$K$21="","",Flights!$K$21) -> BC | G44: =IF(Flights!$L$21="","",Flights!$L$21) -> B738MAX | H44: =IF(Flights!$I$21="","",Flights!$I$21) -> 46322.618 | I44: =IF(Flights!$AJ$21="","",Flights!$AJ$21) -> 0 | J44: =IF(Flights!$AK$21="","",Flights!$AK$21) -> 0 | K44: =IF(Flights!$AL$21="","",Flights!$AL$21) -> 0 | L44: =IF(Flights!$AM$21="","",Flights!$AM$21) -> 0 | M44: =IF(Flights!$AN$21="","",Flights!$AN$21) -> 0 | N44: =IF(Flights!$AP$21="","",Flights!$AP$21) -> 0 | O44: =IF(Flights!$AQ$21="","",Flights!$AQ$21) -> 0 | P44: =IF(Flights!$AR$21="","",Flights!$AR$21) -> 2 | Q44: =IF(Flights!$AS$21="","",Flights!$AS$21) -> 4 | R44: =IF(Flights!$AT$21="","",Flights!$AT$21) -> NOT READY – DOCUMENTS
...

Sheet Flights
A1: Flight register
G2: Source: Skytrax Agenda 2026 slide (schedule) and STD UPLIFT INFORMATION.xlsx (uplift). Yellow = input. Times: STD/STA in local time of the departure/arrival station; due times computed from STD in UTC.
A4: Flight ID | B4: Itin | C4: Seq | D4: Date | E4: Day | F4: Flight No | G4: Dep | H4: Arr | I4: STD local | J4: STA local | K4: Class assessed | L4: Fleet (schedule) | M4: Aircraft ref type (STD UPLIFT INFO) | N4: Tail / Reg (input) | O4: Seat | P4: Transit | Q4: Remark | R4: Sector key | S4: Region | T4: Service (ref) | U4: Ref uplift stns | V4: Meal uplift stn | W4: Round-trip catered from KUL: agenda candidate carrying flight | X4: Caterer (input) | Y4: Flight PIC (input) | Z4: Dep UTC offset (h) | AA4: STD UTC | AB4: Block time (h) | AC4: T-7D due UTC | AD4: T-24H due UTC | AE4: T-12H prep due UTC | AF4: Uplift due UTC (= STD) | AG4: T-7D due local (meal uplift stn) | AH4: T-24H due local | AI4: T-12H prep due local | AJ4: T-7D % | AK4: T-24H % | AL4: T-12H prep % | AM4: Uplift % | AN4: Overall % | AO4: Open required checks | AP4: Overdue | AQ4: Open discrepancies | AR4: Docs outstanding | AS4: Clarifications open | AT4: READINESS | AU4: Invalid entries | AV4: Checks completed | AW4: Checks in scope | AX4: Inbound carrying flight: KUL departure (UTC, input) | AY4: KUL loading deadline for KUL-sourced items (UTC) | AZ4: Carrying flight earliest arrival at departure stn (UTC) | BA4: First on-board confirmation (UTC) | BB4: Wording flags to review
A5: F01 | B5: 1 | C5: 1 | D5: 46303 | E5: THU | F5: MH0001 | G5: LHR | H5: KUL | I5: 46303.899 | J5: 46304.743 | K5: EY | L5: A350 | M5: A350-900: A359 (9M-MAB..MAG) or A350 (9M-MAH) - tail to confirm | O5: 14C | P5: - | R5: KUL/LHR/KUL | S5: EUR | T5: 2.5 Meal (Meal) | U5: KUL/LHR | V5: LHR | Z5: =IF(AND(INDEX(TZ_DSTS,MATCH(G5,TZ_STN,0))<>"",(I5-INDEX(TZ_STD,MATCH(G5,TZ_STN,0))/24)>=INDEX(TZ_DSTS,MATCH(G5,TZ_STN,0)),(I5-INDEX(TZ_STD,MATCH(G5,TZ_STN,0))/24)<INDEX(TZ_DSTE,MATCH(G5,TZ_STN,0))),INDEX(TZ_DST,MATCH(G5,TZ_STN,0)),INDEX(TZ_STD,MATCH(G5,TZ_STN,0))) -> 1 | AA5: =I5-Z5/24 -> 46303.858 | AB5: =(J5-(IF(AND(INDEX(TZ_DSTS,MATCH(H5,TZ_STN,0))<>"",(J5-INDEX(TZ_STD,MATCH(H5,TZ_STN,0))/24)>=INDEX(TZ_DSTS,MATCH(H5,TZ_STN,0)),(J5-INDEX(TZ_STD,MATCH(H5,TZ_STN,0))/24)<INDEX(TZ_DSTE,MATCH(H5,TZ_STN,0))),INDEX(TZ_DST,MATCH(H5,TZ_STN,0)),INDEX(TZ_STD,MATCH(H5,TZ_STN,0))))/24-AA5)*24 -> 13.25 | AC5: =AA5-7 -> 46296.858 | AD5: =AA5-1 -> 46302.858 | AE5: =AA5-0.5 -> 46303.358 | AF5: =AA5 -> 46303.858 | AG5: =AC5+(IF(AND(INDEX(TZ_DSTS,MATCH(V5,TZ_STN,0))<>"",AC5>=INDEX(TZ_DSTS,MATCH(V5,TZ_STN,0)),AC5<INDEX(TZ_DSTE,MATCH(V5,TZ_STN,0))),INDEX(TZ_DST,MATCH(V5,TZ_STN,0)),INDEX(TZ_STD,MATCH(V5,TZ_STN,0))))/24 -> 46296.899 | AH5: =AD5+(IF(AND(INDEX(TZ_DSTS,MATCH(V5,TZ_STN,0))<>"",AD5>=INDEX(TZ_DSTS,MATCH(V5,TZ_STN,0)),AD5<INDEX(TZ_DSTE,MATCH(V5,TZ_STN,0))),INDEX(TZ_DST,MATCH(V5,TZ_STN,0)),INDEX(TZ_STD,MATCH(V5,TZ_STN,0))))/24 -> 46302.899 | AI5: =AE5+(IF(AND(INDEX(TZ_DSTS,MATCH(V5,TZ_STN,0))<>"",AE5>=INDEX(TZ_DSTS,MATCH(V5,TZ_STN,0)),AE5<INDEX(TZ_DSTE,MATCH(V5,TZ_STN,0))),INDEX(TZ_DST,MATCH(V5,TZ_STN,0)),INDEX(TZ_STD,MATCH(V5,TZ_STN,0))))/24 -> 46303.399 | AJ5: =IFERROR(SUMIFS(Checks!$AJ$5:$AJ$748,Checks!$B$5:$B$748,$A5,Checks!$G$5:$G$748,"T-7D")/SUMIFS(Checks!$AI$5:$AI$748,Checks!$B$5:$B$748,$A5,Checks!$G$5:$G$748,"T-7D"),"n/a") -> 0 | AK5: =IFERROR(SUMIFS(Checks!$AJ$5:$AJ$748,Checks!$B$5:$B$748,$A5,Checks!$G$5:$G$748,"T-24H")/SUMIFS(Checks!$AI$5:$AI$748,Checks!$B$5:$B$748,$A5,Checks!$G$5:$G$748,"T-24H"),"n/a") -> 0 | AL5: =IFERROR(SUMIFS(Checks!$AJ$5:$AJ$748,Checks!$B$5:$B$748,$A5,Checks!$G$5:$G$748,"T-12H PREP")/SUMIFS(Checks!$AI$5:$AI$748,Checks!$B$5:$B$748,$A5,Checks!$G$5:$G$748,"T-12H PREP"),"n/a") -> 0 | AM5: =IFERROR(SUMIFS(Checks!$AJ$5:$AJ$748,Checks!$B$5:$B$748,$A5,Checks!$G$5:$G$748,"UPLIFT")/SUMIFS(Checks!$AI$5:$AI$748,Checks!$B$5:$B$748,$A5,Checks!$G$5:$G$748,"UPLIFT"),"n/a") -> 0 | AN5: =IFERROR(SUMIFS(Checks!$AJ$5:$AJ$748,Checks!$B$5:$B$748,$A5)/SUMIFS(Checks!$AI$5:$AI$748,Checks!$B$5:$B$748,$A5),"n/a") -> 0 | AO5: =AW5-AV5 -> 24 | AP5: =SUMIFS(Checks!$AK$5:$AK$748,Checks!$B$5:$B$748,$A5) -> 0 | AQ5: =SUMIFS(Checks!$AL$5:$AL$748,Checks!$B$5:$B$748,$A5) -> 0 | AR5: =Documents!P5 -> 2 | AS5: =SUMIFS(Checks!$AN$5:$AN$748,Checks!$B$5:$B$748,$A5,Checks!$H$5:$H$748,"Preparation")+IF(AND(TRIM(L5)="A350",ISNA(MATCH(UPPER(SUBSTITUTE(SUBSTITUTE(TRIM(N5),"-","")," ","")),{"9MMAB","9MMAC","9MMAD","9MMAE","9MMAF","9MMAG","9MMAH"},0))),1,0) -> 2 | AT5: =IF(AND(AW5>0,AO5=0,AQ5=0,AR5=0,AS5=0,AU5=0),"READY",IF(AP5>0,"NOT READY – OVERDUE",IF(AQ5>0,"NOT READY – DISCREPANCY",IF(AU5>0,"NOT READY – INVALID ENTRY",IF(AR5>0,"NOT READY – DOCUMENTS",IF(AS5>0,"NOT READY – CLARIFICATION",IF(AND(AV5>0,SUMIFS(Checks!$AJ$5:$AJ$748,Checks!$B$5:$B$748,$A5,Checks!$H$5:$H$748,"Preparation")=SUMIFS(Checks!$AI$5:$AI$748,Checks!$B$5:$B$748,$A5,Checks!$H$5:$H$748,"Preparation")),"PREP DONE – AWAITING UPLIFT",IF(AV5=0,"NOT STARTED","IN PROGRESS")))))))) -> NOT READY – DOCUMENTS | AU5: =SUMIFS(Checks!$AM$5:$AM$748,Checks!$B$5:$B$748,$A5) -> 0 | AV5: =SUMIFS(Checks!$AJ$5:$AJ$748,Checks!$B$5:$B$748,$A5) -> 0 | AW5: =SUMIFS(Checks!$AI$5:$AI$748,Checks!$B$5:$B$748,$A5) -> 24 | AX5: n/a | AY5: n/a | AZ5: n/a | BA5: =IFERROR(1/(1/_xlfn.MINIFS(Checks!$AG$5:$AG$748,Checks!$B$5:$B$748,$A5,Checks!$H$5:$H$748,"Physical uplift",Checks!$P$5:$P$748,$G5)),"") | BB5: =SUMIFS(Checks!$BG$5:$BG$748,Checks!$B$5:$B$748,$A5) -> 0
A6: F02 | B6: 1 | C6: 2 | D6: 46304 | E6: FRI | F6: MH0727 | G6: KUL | H6: CGK | I6: 46304.91 | J6: 46304.962 | K6: BC | L6: B738MAX | M6: B737-8 (B7M8) | O6: 1C | P6: 4H 00M | Q6: Overnight CGK | R6: KUL/CGK/KUL | S6: ASEAN | T6: 1 Meal (Meal) | U6: KUL/CGK | V6: KUL | Z6: =IF(AND(INDEX(TZ_DSTS,MATCH(G6,TZ_STN,0))<>"",(I6-INDEX(TZ_STD,MATCH(G6,TZ_STN,0))/24)>=INDEX(TZ_DSTS,MATCH(G6,TZ_STN,0)),(I6-INDEX(TZ_STD,MATCH(G6,TZ_STN,0))/24)<INDEX(TZ_DSTE,MATCH(G6,TZ_STN,0))),INDEX(TZ_DST,MATCH(G6,TZ_STN,0)),INDEX(TZ_STD,MATCH(G6,TZ_STN,0))) -> 8 | AA6: =I6-Z6/24 -> 46304.576 | AB6: =(J6-(IF(AND(INDEX(TZ_DSTS,MATCH(H6,TZ_STN,0))<>"",(J6-INDEX(TZ_STD,MATCH(H6,TZ_STN,0))/24)>=INDEX(TZ_DSTS,MATCH(H6,TZ_STN,0)),(J6-INDEX(TZ_STD,MATCH(H6,TZ_STN,0))/24)<INDEX(TZ_DSTE,MATCH(H6,TZ_STN,0))),INDEX(TZ_DST,MATCH(H6,TZ_STN,0)),INDEX(TZ_STD,MATCH(H6,TZ_STN,0))))/24-AA6)*24 -> 2.25 | AC6: =AA6-7 -> 46297.576 | AD6: =AA6-1 -> 46303.576 | AE6: =AA6-0.5 -> 46304.076 | AF6: =AA6 -> 46304.576 | AG6: =AC6+(IF(AND(INDEX(TZ_DSTS,MATCH(V6,TZ_STN,0))<>"",AC6>=INDEX(TZ_DSTS,MATCH(V6,TZ_STN,0)),AC6<INDEX(TZ_DSTE,MATCH(V6,TZ_STN,0))),INDEX(TZ_DST,MATCH(V6,TZ_STN,0)),INDEX(TZ_STD,MATCH(V6,TZ_STN,0))))/24 -> 46297.91 | AH6: =AD6+(IF(AND(INDEX(TZ_DSTS,MATCH(V6,TZ_STN,0))<>"",AD6>=INDEX(TZ_DSTS,MATCH(V6,TZ_STN,0)),AD6<INDEX(TZ_DSTE,MATCH(V6,TZ_STN,0))),INDEX(TZ_DST,MATCH(V6,TZ_STN,0)),INDEX(TZ_STD,MATCH(V6,TZ_STN,0))))/24 -> 46303.91 | AI6: =AE6+(IF(AND(INDEX(TZ_DSTS,MATCH(V6,TZ_STN,0))<>"",AE6>=INDEX(TZ_DSTS,MATCH(V6,TZ_STN,0)),AE6<INDEX(TZ_DSTE,MATCH(V6,TZ_STN,0))),INDEX(TZ_DST,MATCH(V6,TZ_STN,0)),INDEX(TZ_STD,MATCH(V6,TZ_STN,0))))/24 -> 46304.41 | AJ6: =IFERROR(SUMIFS(Checks!$AJ$5:$AJ$748,Checks!$B$5:$B$748,$A6,Checks!$G$5:$G$748,"T-7D")/SUMIFS(Checks!$AI$5:$AI$748,Checks!$B$5:$B$748,$A6,Checks!$G$5:$G$748,"T-7D"),"n/a") -> 0 | AK6: =IFERROR(SUMIFS(Checks!$AJ$5:$AJ$748,Checks!$B$5:$B$748,$A6,Checks!$G$5:$G$748,"T-24H")/SUMIFS(Checks!$AI$5:$AI$748,Checks!$B$5:$B$748,$A6,Checks!$G$5:$G$748,"T-24H"),"n/a") -> 0 | AL6: =IFERROR(SUMIFS(Checks!$AJ$5:$AJ$748,Checks!$B$5:$B$748,$A6,Checks!$G$5:$G$748,"T-12H PREP")/SUMIFS(Checks!$AI$5:$AI$748,Checks!$B$5:$B$748,$A6,Checks!$G$5:$G$748,"T-12H PREP"),"n/a") -> 0 | AM6: =IFERROR(SUMIFS(Checks!$AJ$5:$AJ$748,Checks!$B$5:$B$748,$A6,Checks!$G$5:$G$748,"UPLIFT")/SUMIFS(Checks!$AI$5:$AI$748,Checks!$B$5:$B$748,$A6,Checks!$G$5:$G$748,"UPLIFT"),"n/a") -> 0 | AN6: =IFERROR(SUMIFS(Checks!$AJ$5:$AJ$748,Checks!$B$5:$B$748,$A6)/SUMIFS(Checks!$AI$5:$AI$748,Checks!$B$5:$B$748,$A6),"n/a") -> 0 | AO6: =AW6-AV6 -> 38 | AP6: =SUMIFS(Checks!$AK$5:$AK$748,Checks!$B$5:$B$748,$A6) -> 0 | AQ6: =SUMIFS(Checks!$AL$5:$AL$748,Checks!$B$5:$B$748,$A6) -> 0 | AR6: =Documents!P6 -> 2 | AS6: =SUMIFS(Checks!$AN$5:$AN$748,Checks!$B$5:$B$748,$A6,Checks!$H$5:$H$748,"Preparation")+IF(AND(TRIM(L6)="A350",ISNA(MATCH(UPPER(SUBSTITUTE(SUBSTITUTE(TRIM(N6),"-","")," ","")),{"9MMAB","9MMAC","9MMAD","9MMAE","9MMAF","9MMAG","9MMAH"},0))),1,0) -> 2 | AT6: =IF(AND(AW6>0,AO6=0,AQ6=0,AR6=0,AS6=0,AU6=0),"READY",IF(AP6>0,"NOT READY – OVERDUE",IF(AQ6>0,"NOT READY – DISCREPANCY",IF(AU6>0,"NOT READY – INVALID ENTRY",IF(AR6>0,"NOT READY – DOCUMENTS",IF(AS6>0,"NOT READY – CLARIFICATION",IF(AND(AV6>0,SUMIFS(Checks!$AJ$5:$AJ$748,Checks!$B$5:$B$748,$A6,Checks!$H$5:$H$748,"Preparation")=SUMIFS(Checks!$AI$5:$AI$748,Checks!$B$5:$B$748,$A6,Checks!$H$5:$H$748,"Preparation")),"PREP DONE – AWAITING UPLIFT",IF(AV6=0,"NOT STARTED","IN PROGRESS")))))))) -> NOT READY – DOCUMENTS | AU6: =SUMIFS(Checks!$AM$5:$AM$748,Checks!$B$5:$B$748,$A6) -> 0 | AV6: =SUMIFS(Checks!$AJ$5:$AJ$748,Checks!$B$5:$B$748,$A6) -> 0 | AW6: =SUMIFS(Checks!$AI$5:$AI$748,Checks!$B$5:$B$748,$A6) -> 38 | AX6: n/a | AY6: n/a | AZ6: n/a | BA6: =IFERROR(1/(1/_xlfn.MINIFS(Checks!$AG$5:$AG$748,Checks!$B$5:$B$748,$A6,Checks!$H$5:$H$748,"Physical uplift",Checks!$P$5:$P$748,$G6)),"") | BB6: =SUMIFS(Checks!$BG$5:$BG$748,Checks!$B$5:$B$748,$A6) -> 0
A7: F03 | B7: 1 | C7: 3 | D7: 46305 | E7: SAT | F7: MH0720 | G7: CGK | H7: KUL | I7: 46305.67 | J7: 46305.809 | K7: EY | L7: A333 | M7: A330-300 (A333) | O7: 11C | P7: - | R7: KUL/CGK/KUL | S7: ASEAN | T7: 1 Meal (Meal) | U7: KUL/CGK | V7: CGK | Z7: =IF(AND(INDEX(TZ_DSTS,MATCH(G7,TZ_STN,0))<>"",(I7-INDEX(TZ_STD,MATCH(G7,TZ_STN,0))/24)>=INDEX(TZ_DSTS,MATCH(G7,TZ_STN,0)),(I7-INDEX(TZ_STD,MATCH(G7,TZ_STN,0))/24)<INDEX(TZ_DSTE,MATCH(G7,TZ_STN,0))),INDEX(TZ_DST,MATCH(G7,TZ_STN,0)),INDEX(TZ_STD,MATCH(G7,TZ_STN,0))) -> 7 | AA7: =I7-Z7/24 -> 46305.378 | AB7: =(J7-(IF(AND(INDEX(TZ_DSTS,MATCH(H7,TZ_STN,0))<>"",(J7-INDEX(TZ_STD,MATCH(H7,TZ_STN,0))/24)>=INDEX(TZ_DSTS,MATCH(H7,TZ_STN,0)),(J7-INDEX(TZ_STD,MATCH(H7,TZ_STN,0))/24)<INDEX(TZ_DSTE,MATCH(H7,TZ_STN,0))),INDEX(TZ_DST,MATCH(H7,TZ_STN,0)),INDEX(TZ_STD,MATCH(H7,TZ_STN,0))))/24-AA7)*24 -> 2.3333333 | AC7: =AA7-7 -> 46298.378 | AD7: =AA7-1 -> 46304.378 | AE7: =AA7-0.5 -> 46304.878 | AF7: =AA7 -> 46305.378 | AG7: =AC7+(IF(AND(INDEX(TZ_DSTS,MATCH(V7,TZ_STN,0))<>"",AC7>=INDEX(TZ_DSTS,MATCH(V7,TZ_STN,0)),AC7<INDEX(TZ_DSTE,MATCH(V7,TZ_STN,0))),INDEX(TZ_DST,MATCH(V7,TZ_STN,0)),INDEX(TZ_STD,MATCH(V7,TZ_STN,0))))/24 -> 46298.67 | AH7: =AD7+(IF(AND(INDEX(TZ_DSTS,MATCH(V7,TZ_STN,0))<>"",AD7>=INDEX(TZ_DSTS,MATCH(V7,TZ_STN,0)),AD7<INDEX(TZ_DSTE,MATCH(V7,TZ_STN,0))),INDEX(TZ_DST,MATCH(V7,TZ_STN,0)),INDEX(TZ_STD,MATCH(V7,TZ_STN,0))))/24 -> 46304.67 | AI7: =AE7+(IF(AND(INDEX(TZ_DSTS,MATCH(V7,TZ_STN,0))<>"",AE7>=INDEX(TZ_DSTS,MATCH(V7,TZ_STN,0)),AE7<INDEX(TZ_DSTE,MATCH(V7,TZ_STN,0))),INDEX(TZ_DST,MATCH(V7,TZ_STN,0)),INDEX(TZ_STD,MATCH(V7,TZ_STN,0))))/24 -> 46305.17 | AJ7: =IFERROR(SUMIFS(Checks!$AJ$5:$AJ$748,Checks!$B$5:$B$748,$A7,Checks!$G$5:$G$748,"T-7D")/SUMIFS(Checks!$AI$5:$AI$748,Checks!$B$5:$B$748,$A7,Checks!$G$5:$G$748,"T-7D"),"n/a") -> 0 | AK7: =IFERROR(SUMIFS(Checks!$AJ$5:$AJ$748,Checks!$B$5:$B$748,$A7,Checks!$G$5:$G$748,"T-24H")/SUMIFS(Checks!$AI$5:$AI$748,Checks!$B$5:$B$748,$A7,Checks!$G$5:$G$748,"T-24H"),"n/a") -> 0 | AL7: =IFERROR(SUMIFS(Checks!$AJ$5:$AJ$748,Checks!$B$5:$B$748,$A7,Checks!$G$5:$G$748,"T-12H PREP")/SUMIFS(Checks!$AI$5:$AI$748,Checks!$B$5:$B$748,$A7,Checks!$G$5:$G$748,"T-12H PREP"),"n/a") -> 0 | AM7: =IFERROR(SUMIFS(Checks!$AJ$5:$AJ$748,Checks!$B$5:$B$748,$A7,Checks!$G$5:$G$748,"UPLIFT")/SUMIFS(Checks!$AI$5:$AI$748,Checks!$B$5:$B$748,$A7,Checks!$G$5:$G$748,"UPLIFT"),"n/a") -> 0 | AN7: =IFERROR(SUMIFS(Checks!$AJ$5:$AJ$748,Checks!$B$5:$B$748,$A7)/SUMIFS(Checks!$AI$5:$AI$748,Checks!$B$5:$B$748,$A7),"n/a") -> 0 | AO7: =AW7-AV7 -> 20 | AP7: =SUMIFS(Checks!$AK$5:$AK$748,Checks!$B$5:$B$748,$A7) -> 0 | AQ7: =SUMIFS(Checks!$AL$5:$AL$748,Checks!$B$5:$B$748,$A7) -> 0 | AR7: =Documents!P7 -> 2 | AS7: =SUMIFS(Checks!$AN$5:$AN$748,Checks!$B$5:$B$748,$A7,Checks!$H$5:$H$748,"Preparation")+IF(AND(TRIM(L7)="A350",ISNA(MATCH(UPPER(SUBSTITUTE(SUBSTITUTE(TRIM(N7),"-","")," ","")),{"9MMAB","9MMAC","9MMAD","9MMAE","9MMAF","9MMAG","9MMAH"},0))),1,0) -> 0 | AT7: =IF(AND(AW7>0,AO7=0,AQ7=0,AR7=0,AS7=0,AU7=0),"READY",IF(AP7>0,"NOT READY – OVERDUE",IF(AQ7>0,"NOT READY – DISCREPANCY",IF(AU7>0,"NOT READY – INVALID ENTRY",IF(AR7>0,"NOT READY – DOCUMENTS",IF(AS7>0,"NOT READY – CLARIFICATION",IF(AND(AV7>0,SUMIFS(Checks!$AJ$5:$AJ$748,Checks!$B$5:$B$748,$A7,Checks!$H$5:$H$748,"Preparation")=SUMIFS(Checks!$AI$5:$AI$748,Checks!$B$5:$B$748,$A7,Checks!$H$5:$H$748,"Preparation")),"PREP DONE – AWAITING UPLIFT",IF(AV7=0,"NOT STARTED","IN PROGRESS")))))))) -> NOT READY – DOCUMENTS | AU7: =SUMIFS(Checks!$AM$5:$AM$748,Checks!$B$5:$B$748,$A7) -> 0 | AV7: =SUMIFS(Checks!$AJ$5:$AJ$748,Checks!$B$5:$B$748,$A7) -> 0 | AW7: =SUMIFS(Checks!$AI$5:$AI$748,Checks!$B$5:$B$748,$A7) -> 20 | AX7: n/a | AY7: n/a | AZ7: n/a | BA7: =IFERROR(1/(1/_xlfn.MINIFS(Checks!$AG$5:$AG$748,Checks!$B$5:$B$748,$A7,Checks!$H$5:$H$748,"Physical uplift",Checks!$P$5:$P$748,$G7)),"") | BB7: =SUMIFS(Checks!$BG$5:$BG$748,Checks!$B$5:$B$748,$A7) -> 0
A8: F04 | B8: 1 | C8: 4 | D8: 46305 | E8: SAT | F8: MH0088 | G8: KUL | H8: NRT | I8: 46305.979 | J8: 46306.319 | K8: BC | L8: A350 | M8: A350-900: A359 (9M-MAB..MAG) or A350 (9M-MAH) - tail to confirm | O8: 1A | P8: 4H 05M | Q8: Overnight NRT | R8: KUL/NRT/KUL | S8: NORTH ASIA | T8: 1.5 Meal (Meal) | U8: KUL/NRT | V8: KUL | Z8: =IF(AND(INDEX(TZ_DSTS,MATCH(G8,TZ_STN,0))<>"",(I8-INDEX(TZ_STD,MATCH(G8,TZ_STN,0))/24)>=INDEX(TZ_DSTS,MATCH(G8,TZ_STN,0)),(I8-INDEX(TZ_STD,MATCH(G8,TZ_STN,0))/24)<INDEX(TZ_DSTE,MATCH(G8,TZ_STN,0))),INDEX(TZ_DST,MATCH(G8,TZ_STN,0)),INDEX(TZ_STD,MATCH(G8,TZ_STN,0))) -> 8 | AA8: =I8-Z8/24 -> 46305.646 | AB8: =(J8-(IF(AND(INDEX(TZ_DSTS,MATCH(H8,TZ_STN,0))<>"",(J8-INDEX(TZ_STD,MATCH(H8,TZ_STN,0))/24)>=INDEX(TZ_DSTS,MATCH(H8,TZ_STN,0)),(J8-INDEX(TZ_STD,MATCH(H8,TZ_STN,0))/24)<INDEX(TZ_DSTE,MATCH(H8,TZ_STN,0))),INDEX(TZ_DST,MATCH(H8,TZ_STN,0)),INDEX(TZ_STD,MATCH(H8,TZ_STN,0))))/24-AA8)*24 -> 7.1666667 | AC8: =AA8-7 -> 46298.646 | AD8: =AA8-1 -> 46304.646 | AE8: =AA8-0.5 -> 46305.146 | AF8: =AA8 -> 46305.646 | AG8: =AC8+(IF(AND(INDEX(TZ_DSTS,MATCH(V8,TZ_STN,0))<>"",AC8>=INDEX(TZ_DSTS,MATCH(V8,TZ_STN,0)),AC8<INDEX(TZ_DSTE,MATCH(V8,TZ_STN,0))),INDEX(TZ_DST,MATCH(V8,TZ_STN,0)),INDEX(TZ_STD,MATCH(V8,TZ_STN,0))))/24 -> 46298.979 | AH8: =AD8+(IF(AND(INDEX(TZ_DSTS,MATCH(V8,TZ_STN,0))<>"",AD8>=INDEX(TZ_DSTS,MATCH(V8,TZ_STN,0)),AD8<INDEX(TZ_DSTE,MATCH(V8,TZ_STN,0))),INDEX(TZ_DST,MATCH(V8,TZ_STN,0)),INDEX(TZ_STD,MATCH(V8,TZ_STN,0))))/24 -> 46304.979 | AI8: =AE8+(IF(AND(INDEX(TZ_DSTS,MATCH(V8,TZ_STN,0))<>"",AE8>=INDEX(TZ_DSTS,MATCH(V8,TZ_STN,0)),AE8<INDEX(TZ_DSTE,MATCH(V8,TZ_STN,0))),INDEX(TZ_DST,MATCH(V8,TZ_STN,0)),INDEX(TZ_STD,MATCH(V8,TZ_STN,0))))/24 -> 46305.479 | AJ8: =IFERROR(SUMIFS(Checks!$AJ$5:$AJ$748,Checks!$B$5:$B$748,$A8,Checks!$G$5:$G$748,"T-7D")/SUMIFS(Checks!$AI$5:$AI$748,Checks!$B$5:$B$748,$A8,Checks!$G$5:$G$748,"T-7D"),"n/a") -> 0 | AK8: =IFERROR(SUMIFS(Checks!$AJ$5:$AJ$748,Checks!$B$5:$B$748,$A8,Checks!$G$5:$G$748,"T-24H")/SUMIFS(Checks!$AI$5:$AI$748,Checks!$B$5:$B$748,$A8,Checks!$G$5:$G$748,"T-24H"),"n/a") -> 0 | AL8: =IFERROR(SUMIFS(Checks!$AJ$5:$AJ$748,Checks!$B$5:$B$748,$A8,Checks!$G$5:$G$748,"T-12H PREP")/SUMIFS(Checks!$AI$5:$AI$748,Checks!$B$5:$B$748,$A8,Checks!$G$5:$G$748,"T-12H PREP"),"n/a") -> 0 | AM8: =IFERROR(SUMIFS(Checks!$AJ$5:$AJ$748,Checks!$B$5:$B$748,$A8,Checks!$G$5:$G$748,"UPLIFT")/SUMIFS(Checks!$AI$5:$AI$748,Checks!$B$5:$B$748,$A8,Checks!$G$5:$G$748,"UPLIFT"),"n/a") -> 0 | AN8: =IFERROR(SUMIFS(Checks!$AJ$5:$AJ$748,Checks!$B$5:$B$748,$A8)/SUMIFS(Checks!$AI$5:$AI$748,Checks!$B$5:$B$748,$A8),"n/a") -> 0 | AO8: =AW8-AV8 -> 46 | AP8: =SUMIFS(Checks!$AK$5:$AK$748,Checks!$B$5:$B$748,$A8) -> 0 | AQ8: =SUMIFS(Checks!$AL$5:$AL$748,Checks!$B$5:$B$748,$A8) -> 0 | AR8: =Documents!P8 -> 2 | AS8: =SUMIFS(Checks!$AN$5:$AN$748,Checks!$B$5:$B$748,$A8,Checks!$H$5:$H$748,"Preparation")+IF(AND(TRIM(L8)="A350",ISNA(MATCH(UPPER(SUBSTITUTE(SUBSTITUTE(TRIM(N8),"-","")," ","")),{"9MMAB","9MMAC","9MMAD","9MMAE","9MMAF","9MMAG","9MMAH"},0))),1,0) -> 1 | AT8: =IF(AND(AW8>0,AO8=0,AQ8=0,AR8=0,AS8=0,AU8=0),"READY",IF(AP8>0,"NOT READY – OVERDUE",IF(AQ8>0,"NOT READY – DISCREPANCY",IF(AU8>0,"NOT READY – INVALID ENTRY",IF(AR8>0,"NOT READY – DOCUMENTS",IF(AS8>0,"NOT READY – CLARIFICATION",IF(AND(AV8>0,SUMIFS(Checks!$AJ$5:$AJ$748,Checks!$B$5:$B$748,$A8,Checks!$H$5:$H$748,"Preparation")=SUMIFS(Checks!$AI$5:$AI$748,Checks!$B$5:$B$748,$A8,Checks!$H$5:$H$748,"Preparation")),"PREP DONE – AWAITING UPLIFT",IF(AV8=0,"NOT STARTED","IN PROGRESS")))))))) -> NOT READY – DOCUMENTS | AU8: =SUMIFS(Checks!$AM$5:$AM$748,Checks!$B$5:$B$748,$A8) -> 0 | AV8: =SUMIFS(Checks!$AJ$5:$AJ$748,Checks!$B$5:$B$748,$A8) -> 0 | AW8: =SUMIFS(Checks!$AI$5:$AI$748,Checks!$B$5:$B$748,$A8) -> 46 | AX8: n/a | AY8: n/a | AZ8: n/a | BA8: =IFERROR(1/(1/_xlfn.MINIFS(Checks!$AG$5:$AG$748,Checks!$B$5:$B$748,$A8,Checks!$H$5:$H$748,"Physical uplift",Checks!$P$5:$P$748,$G8)),"") | BB8: =SUMIFS(Checks!$BG$5:$BG$748,Checks!$B$5:$B$748,$A8) -> 0
A9: F05 | B9: 1 | C9: 5 | D9: 46310 | E9: THU | F9: MH0089 | G9: NRT | H9: KUL | I9: 46310.42 | J9: 46310.698 | K9: EY | L9: A350 | M9: A350-900: A359 (9M-MAB..MAG) or A350 (9M-MAH) - tail to confirm | O9: 9K | P9: - | R9: KUL/NRT/KUL | S9: NORTH ASIA | T9: 1.5 Meal (Meal) | U9: KUL/NRT | V9: NRT | Z9: =IF(AND(INDEX(TZ_DSTS,MATCH(G9,TZ_STN,0))<>"",(I9-INDEX(TZ_STD,MATCH(G9,TZ_STN,0))/24)>=INDEX(TZ_DSTS,MATCH(G9,TZ_STN,0)),(I9-INDEX(TZ_STD,MATCH(G9,TZ_STN,0))/24)<INDEX(TZ_DSTE,MATCH(G9,TZ_STN,0))),INDEX(TZ_DST,MATCH(G9,TZ_STN,0)),INDEX(TZ_STD,MATCH(G9,TZ_STN,0))) -> 9 | AA9: =I9-Z9/24 -> 46310.045 | AB9: =(J9-(IF(AND(INDEX(TZ_DSTS,MATCH(H9,TZ_STN,0))<>"",(J9-INDEX(TZ_STD,MATCH(H9,TZ_STN,0))/24)>=INDEX(TZ_DSTS,MATCH(H9,TZ_STN,0)),(J9-INDEX(TZ_STD,MATCH(H9,TZ_STN,0))/24)<INDEX(TZ_DSTE,MATCH(H9,TZ_STN,0))),INDEX(TZ_DST,MATCH(H9,TZ_STN,0)),INDEX(TZ_STD,MATCH(H9,TZ_STN,0))))/24-AA9)*24 -> 7.6666667 | AC9: =AA9-7 -> 46303.045 | AD9: =AA9-1 -> 46309.045 | AE9: =AA9-0.5 -> 46309.545 | AF9: =AA9 -> 46310.045 | AG9: =AC9+(IF(AND(INDEX(TZ_DSTS,MATCH(V9,TZ_STN,0))<>"",AC9>=INDEX(TZ_DSTS,MATCH(V9,TZ_STN,0)),AC9<INDEX(TZ_DSTE,MATCH(V9,TZ_STN,0))),INDEX(TZ_DST,MATCH(V9,TZ_STN,0)),INDEX(TZ_STD,MATCH(V9,TZ_STN,0))))/24 -> 46303.42 | AH9: =AD9+(IF(AND(INDEX(TZ_DSTS,MATCH(V9,TZ_STN,0))<>"",AD9>=INDEX(TZ_DSTS,MATCH(V9,TZ_STN,0)),AD9<INDEX(TZ_DSTE,MATCH(V9,TZ_STN,0))),INDEX(TZ_DST,MATCH(V9,TZ_STN,0)),INDEX(TZ_STD,MATCH(V9,TZ_STN,0))))/24 -> 46309.42 | AI9: =AE9+(IF(AND(INDEX(TZ_DSTS,MATCH(V9,TZ_STN,0))<>"",AE9>=INDEX(TZ_DSTS,MATCH(V9,TZ_STN,0)),AE9<INDEX(TZ_DSTE,MATCH(V9,TZ_STN,0))),INDEX(TZ_DST,MATCH(V9,TZ_STN,0)),INDEX(TZ_STD,MATCH(V9,TZ_STN,0))))/24 -> 46309.92 | AJ9: =IFERROR(SUMIFS(Checks!$AJ$5:$AJ$748,Checks!$B$5:$B$748,$A9,Checks!$G$5:$G$748,"T-7D")/SUMIFS(Checks!$AI$5:$AI$748,Checks!$B$5:$B$748,$A9,Checks!$G$5:$G$748,"T-7D"),"n/a") -> 0 | AK9: =IFERROR(SUMIFS(Checks!$AJ$5:$AJ$748,Checks!$B$5:$B$748,$A9,Checks!$G$5:$G$748,"T-24H")/SUMIFS(Checks!$AI$5:$AI$748,Checks!$B$5:$B$748,$A9,Checks!$G$5:$G$748,"T-24H"),"n/a") -> 0 | AL9: =IFERROR(SUMIFS(Checks!$AJ$5:$AJ$748,Checks!$B$5:$B$748,$A9,Checks!$G$5:$G$748,"T-12H PREP")/SUMIFS(Checks!$AI$5:$AI$748,Checks!$B$5:$B$748,$A9,Checks!$G$5:$G$748,"T-12H PREP"),"n/a") -> 0 | AM9: =IFERROR(SUMIFS(Checks!$AJ$5:$AJ$748,Checks!$B$5:$B$748,$A9,Checks!$G$5:$G$748,"UPLIFT")/SUMIFS(Checks!$AI$5:$AI$748,Checks!$B$5:$B$748,$A9,Checks!$G$5:$G$748,"UPLIFT"),"n/a") -> 0 | AN9: =IFERROR(SUMIFS(Checks!$AJ$5:$AJ$748,Checks!$B$5:$B$748,$A9)/SUMIFS(Checks!$AI$5:$AI$748,Checks!$B$5:$B$748,$A9),"n/a") -> 0 | AO9: =AW9-AV9 -> 28 | AP9: =SUMIFS(Checks!$AK$5:$AK$748,Checks!$B$5:$B$748,$A9) -> 0 | AQ9: =SUMIFS(Checks!$AL$5:$AL$748,Checks!$B$5:$B$748,$A9) -> 0 | AR9: =Documents!P9 -> 2 | AS9: =SUMIFS(Checks!$AN$5:$AN$748,Checks!$B$5:$B$748,$A9,Checks!$H$5:$H$748,"Preparation")+IF(AND(TRIM(L9)="A350",ISNA(MATCH(UPPER(SUBSTITUTE(SUBSTITUTE(TRIM(N9),"-","")," ","")),{"9MMAB","9MMAC","9MMAD","9MMAE","9MMAF","9MMAG","9MMAH"},0))),1,0) -> 4 | AT9: =IF(AND(AW9>0,AO9=0,AQ9=0,AR9=0,AS9=0,AU9=0),"READY",IF(AP9>0,"NOT READY – OVERDUE",IF(AQ9>0,"NOT READY – DISCREPANCY",IF(AU9>0,"NOT READY – INVALID ENTRY",IF(AR9>0,"NOT READY – DOCUMENTS",IF(AS9>0,"NOT READY – CLARIFICATION",IF(AND(AV9>0,SUMIFS(Checks!$AJ$5:$AJ$748,Checks!$B$5:$B$748,$A9,Checks!$H$5:$H$748,"Preparation")=SUMIFS(Checks!$AI$5:$AI$748,Checks!$B$5:$B$748,$A9,Checks!$H$5:$H$748,"Preparation")),"PREP DONE – AWAITING UPLIFT",IF(AV9=0,"NOT STARTED","IN PROGRESS")))))))) -> NOT READY – DOCUMENTS | AU9: =SUMIFS(Checks!$AM$5:$AM$748,Checks!$B$5:$B$748,$A9) -> 0 | AV9: =SUMIFS(Checks!$AJ$5:$AJ$748,Checks!$B$5:$B$748,$A9) -> 0 | AW9: =SUMIFS(Checks!$AI$5:$AI$748,Checks!$B$5:$B$748,$A9) -> 28 | AY9: =ROUND((IF(ISNUMBER(AX9),AX9,AA9-MIN($AB$8)/24)-UpliftWindowH/24)*1440,0)/1440 -> 46309.497 | AZ9: =ROUND((AY9+UpliftWindowH/24+MIN($AB$8)/24)*1440,0)/1440 -> 46310.045 | BA9: =IFERROR(1/(1/_xlfn.MINIFS(Checks!$AG$5:$AG$748,Checks!$B$5:$B$748,$A9,Checks!$H$5:$H$748,"Physical uplift",Checks!$P$5:$P$748,$G9)),"") | BB9: =SUMIFS(Checks!$BG$5:$BG$748,Checks!$B$5:$B$748,$A9) -> 0
A10: F06 | B10: 1 | C10: 6 | D10: 46310 | E10: THU | F10: MH0002 | G10: KUL | H10: LHR | I10: 46310.972 | J10: 46311.247 | K10: BC | L10: A350 | M10: A350-900: A359 (9M-MAB..MAG) or A350 (9M-MAH) - tail to confirm | O10: 2K | P10: 6H 35M | R10: KUL/LHR/KUL | S10: EUR | T10: 2.5 Meal (Meal) | U10: KUL/LHR | V10: KUL | Z10: =IF(AND(INDEX(TZ_DSTS,MATCH(G10,TZ_STN,0))<>"",(I10-INDEX(TZ_STD,MATCH(G10,TZ_STN,0))/24)>=INDEX(TZ_DSTS,MATCH(G10,TZ_STN,0)),(I10-INDEX(TZ_STD,MATCH(G10,TZ_STN,0))/24)<INDEX(TZ_DSTE,MATCH(G10,TZ_STN,0))),INDEX(TZ_DST,MATCH(G10,TZ_STN,0)),INDEX(TZ_STD,MATCH(G10,TZ_STN,0))) -> 8 | AA10: =I10-Z10/24 -> 46310.639 | AB10: =(J10-(IF(AND(INDEX(TZ_DSTS,MATCH(H10,TZ_STN,0))<>"",(J10-INDEX(TZ_STD,MATCH(H10,TZ_STN,0))/24)>=INDEX(TZ_DSTS,MATCH(H10,TZ_STN,0)),(J10-INDEX(TZ_STD,MATCH(H10,TZ_STN,0))/24)<INDEX(TZ_DSTE,MATCH(H10,TZ_STN,0))),INDEX(TZ_DST,MATCH(H10,TZ_STN,0)),INDEX(TZ_STD,MATCH(H10,TZ_STN,0))))/24-AA10)*24 -> 13.583333 | AC10: =AA10-7 -> 46303.639 | AD10: =AA10-1 -> 46309.639 | AE10: =AA10-0.5 -> 46310.139 | AF10: =AA10 -> 46310.639 | AG10: =AC10+(IF(AND(INDEX(TZ_DSTS,MATCH(V10,TZ_STN,0))<>"",AC10>=INDEX(TZ_DSTS,MATCH(V10,TZ_STN,0)),AC10<INDEX(TZ_DSTE,MATCH(V10,TZ_STN,0))),INDEX(TZ_DST,MATCH(V10,TZ_STN,0)),INDEX(TZ_STD,MATCH(V10,TZ_STN,0))))/24 -> 46303.972 | AH10: =AD10+(IF(AND(INDEX(TZ_DSTS,MATCH(V10,TZ_STN,0))<>"",AD10>=INDEX(TZ_DSTS,MATCH(V10,TZ_STN,0)),AD10<INDEX(TZ_DSTE,MATCH(V10,TZ_STN,0))),INDEX(TZ_DST,MATCH(V10,TZ_STN,0)),INDEX(TZ_STD,MATCH(V10,TZ_STN,0))))/24 -> 46309.972 | AI10: =AE10+(IF(AND(INDEX(TZ_DSTS,MATCH(V10,TZ_STN,0))<>"",AE10>=INDEX(TZ_DSTS,MATCH(V10,TZ_STN,0)),AE10<INDEX(TZ_DSTE,MATCH(V10,TZ_STN,0))),INDEX(TZ_DST,MATCH(V10,TZ_STN,0)),INDEX(TZ_STD,MATCH(V10,TZ_STN,0))))/24 -> 46310.472 | AJ10: =IFERROR(SUMIFS(Checks!$AJ$5:$AJ$748,Checks!$B$5:$B$748,$A10,Checks!$G$5:$G$748,"T-7D")/SUMIFS(Checks!$AI$5:$AI$748,Checks!$B$5:$B$748,$A10,Checks!$G$5:$G$748,"T-7D"),"n/a") -> 0 | AK10: =IFERROR(SUMIFS(Checks!$AJ$5:$AJ$748,Checks!$B$5:$B$748,$A10,Checks!$G$5:$G$748,"T-24H")/SUMIFS(Checks!$AI$5:$AI$748,Checks!$B$5:$B$748,$A10,Checks!$G$5:$G$748,"T-24H"),"n/a") -> 0 | AL10: =IFERROR(SUMIFS(Checks!$AJ$5:$AJ$748,Checks!$B$5:$B$748,$A10,Checks!$G$5:$G$748,"T-12H PREP")/SUMIFS(Checks!$AI$5:$AI$748,Checks!$B$5:$B$748,$A10,Checks!$G$5:$G$748,"T-12H PREP"),"n/a") -> 0 | AM10: =IFERROR(SUMIFS(Checks!$AJ$5:$AJ$748,Checks!$B$5:$B$748,$A10,Checks!$G$5:$G$748,"UPLIFT")/SUMIFS(Checks!$AI$5:$AI$748,Checks!$B$5:$B$748,$A10,Checks!$G$5:$G$748,"UPLIFT"),"n/a") -> 0 | AN10: =IFERROR(SUMIFS(Checks!$AJ$5:$AJ$748,Checks!$B$5:$B$748,$A10)/SUMIFS(Checks!$AI$5:$AI$748,Checks!$B$5:$B$748,$A10),"n/a") -> 0 | AO10: =AW10-AV10 -> 46 | AP10: =SUMIFS(Checks!$AK$5:$AK$748,Checks!$B$5:$B$748,$A10) -> 0 | AQ10: =SUMIFS(Checks!$AL$5:$AL$748,Checks!$B$5:$B$748,$A10) -> 0 | AR10: =Documents!P10 -> 2 | AS10: =SUMIFS(Checks!$AN$5:$AN$748,Checks!$B$5:$B$748,$A10,Checks!$H$5:$H$748,"Preparation")+IF(AND(TRIM(L10)="A350",ISNA(MATCH(UPPER(SUBSTITUTE(SUBSTITUTE(TRIM(N10),"-","")," ","")),{"9MMAB","9MMAC","9MMAD","9MMAE","9MMAF","9MMAG","9MMAH"},0))),1,0) -> 2 | AT10: =IF(AND(AW10>0,AO10=0,AQ10=0,AR10=0,AS10=0,AU10=0),"READY",IF(AP10>0,"NOT READY – OVERDUE",IF(AQ10>0,"NOT READY – DISCREPANCY",IF(AU10>0,"NOT READY – INVALID ENTRY",IF(AR10>0,"NOT READY – DOCUMENTS",IF(AS10>0,"NOT READY – CLARIFICATION",IF(AND(AV10>0,SUMIFS(Checks!$AJ$5:$AJ$748,Checks!$B$5:$B$748,$A10,Checks!$H$5:$H$748,"Preparation")=SUMIFS(Checks!$AI$5:$AI$748,Checks!$B$5:$B$748,$A10,Checks!$H$5:$H$748,"Preparation")),"PREP DONE – AWAITING UPLIFT",IF(AV10=0,"NOT STARTED","IN PROGRESS")))))))) -> NOT READY – DOCUMENTS | AU10: =SUMIFS(Checks!$AM$5:$AM$748,Checks!$B$5:$B$748,$A10) -> 0 | AV10: =SUMIFS(Checks!$AJ$5:$AJ$748,Checks!$B$5:$B$748,$A10) -> 0 | AW10: =SUMIFS(Checks!$AI$5:$AI$748,Checks!$B$5:$B$748,$A10) -> 46 | AX10: n/a | AY10: n/a | AZ10: n/a | BA10: =IFERROR(1/(1/_xlfn.MINIFS(Checks!$AG$5:$AG$748,Checks!$B$5:$B$748,$A10,Checks!$H$5:$H$748,"Physical uplift",Checks!$P$5:$P$748,$G10)),"") | BB10: =SUMIFS(Checks!$BG$5:$BG$748,Checks!$B$5:$B$748,$A10) -> 0
A11: F07 | B11: 2 | C11: 7 | D11: 46304 | E11: FRI | F11: MH0003 | G11: LHR | H11: KUL | I11: 46304.458 | J11: 46305.281 | K11: BC | L11: A350 | M11: A350-900: A359 (9M-MAB..MAG) or A350 (9M-MAH) - tail to confirm | O11: 2A | P11: - | R11: KUL/LHR/KUL | S11: EUR | T11: 2.5 Meal (Meal) | U11: KUL/LHR | V11: LHR | Z11: =IF(AND(INDEX(TZ_DSTS,MATCH(G11,TZ_STN,0))<>"",(I11-INDEX(TZ_STD,MATCH(G11,TZ_STN,0))/24)>=INDEX(TZ_DSTS,MATCH(G11,TZ_STN,0)),(I11-INDEX(TZ_STD,MATCH(G11,TZ_STN,0))/24)<INDEX(TZ_DSTE,MATCH(G11,TZ_STN,0))),INDEX(TZ_DST,MATCH(G11,TZ_STN,0)),INDEX(TZ_STD,MATCH(G11,TZ_STN,0))) -> 1 | AA11: =I11-Z11/24 -> 46304.417 | AB11: =(J11-(IF(AND(INDEX(TZ_DSTS,MATCH(H11,TZ_STN,0))<>"",(J11-INDEX(TZ_STD,MATCH(H11,TZ_STN,0))/24)>=INDEX(TZ_DSTS,MATCH(H11,TZ_STN,0)),(J11-INDEX(TZ_STD,MATCH(H11,TZ_STN,0))/24)<INDEX(TZ_DSTE,MATCH(H11,TZ_STN,0))),INDEX(TZ_DST,MATCH(H11,TZ_STN,0)),INDEX(TZ_STD,MATCH(H11,TZ_STN,0))))/24-AA11)*24 -> 12.75 | AC11: =AA11-7 -> 46297.417 | AD11: =AA11-1 -> 46303.417 | AE11: =AA11-0.5 -> 46303.917 | AF11: =AA11 -> 46304.417 | AG11: =AC11+(IF(AND(INDEX(TZ_DSTS,MATCH(V11,TZ_STN,0))<>"",AC11>=INDEX(TZ_DSTS,MATCH(V11,TZ_STN,0)),AC11<INDEX(TZ_DSTE,MATCH(V11,TZ_STN,0))),INDEX(TZ_DST,MATCH(V11,TZ_STN,0)),INDEX(TZ_STD,MATCH(V11,TZ_STN,0))))/24 -> 46297.458 | AH11: =AD11+(IF(AND(INDEX(TZ_DSTS,MATCH(V11,TZ_STN,0))<>"",AD11>=INDEX(TZ_DSTS,MATCH(V11,TZ_STN,0)),AD11<INDEX(TZ_DSTE,MATCH(V11,TZ_STN,0))),INDEX(TZ_DST,MATCH(V11,TZ_STN,0)),INDEX(TZ_STD,MATCH(V11,TZ_STN,0))))/24 -> 46303.458 | AI11: =AE11+(IF(AND(INDEX(TZ_DSTS,MATCH(V11,TZ_STN,0))<>"",AE11>=INDEX(TZ_DSTS,MATCH(V11,TZ_STN,0)),AE11<INDEX(TZ_DSTE,MATCH(V11,TZ_STN,0))),INDEX(TZ_DST,MATCH(V11,TZ_STN,0)),INDEX(TZ_STD,MATCH(V11,TZ_STN,0))))/24 -> 46303.958 | AJ11: =IFERROR(SUMIFS(Checks!$AJ$5:$AJ$748,Checks!$B$5:$B$748,$A11,Checks!$G$5:$G$748,"T-7D")/SUMIFS(Checks!$AI$5:$AI$748,Checks!$B$5:$B$748,$A11,Checks!$G$5:$G$748,"T-7D"),"n/a") -> 0 | AK11: =IFERROR(SUMIFS(Checks!$AJ$5:$AJ$748,Checks!$B$5:$B$748,$A11,Checks!$G$5:$G$748,"T-24H")/SUMIFS(Checks!$AI$5:$AI$748,Checks!$B$5:$B$748,$A11,Checks!$G$5:$G$748,"T-24H"),"n/a") -> 0 | AL11: =IFERROR(SUMIFS(Checks!$AJ$5:$AJ$748,Checks!$B$5:$B$748,$A11,Checks!$G$5:$G$748,"T-12H PREP")/SUMIFS(Checks!$AI$5:$AI$748,Checks!$B$5:$B$748,$A11,Checks!$G$5:$G$748,"T-12H PREP"),"n/a") -> 0 | AM11: =IFERROR(SUMIFS(Checks!$AJ$5:$AJ$748,Checks!$B$5:$B$748,$A11,Checks!$G$5:$G$748,"UPLIFT")/SUMIFS(Checks!$AI$5:$AI$748,Checks!$B$5:$B$748,$A11,Checks!$G$5:$G$748,"UPLIFT"),"n/a") -> 0 | AN11: =IFERROR(SUMIFS(Checks!$AJ$5:$AJ$748,Checks!$B$5:$B$748,$A11)/SUMIFS(Checks!$AI$5:$AI$748,Checks!$B$5:$B$748,$A11),"n/a") -> 0 | AO11: =AW11-AV11 -> 48 | AP11: =SUMIFS(Checks!$AK$5:$AK$748,Checks!$B$5:$B$748,$A11) -> 0 | AQ11: =SUMIFS(Checks!$AL$5:$AL$748,Checks!$B$5:$B$748,$A11) -> 0 | AR11: =Documents!P11 -> 2 | AS11: =SUMIFS(Checks!$AN$5:$AN$748,Checks!$B$5:$B$748,$A11,Checks!$H$5:$H$748,"Preparation")+IF(AND(TRIM(L11)="A350",ISNA(MATCH(UPPER(SUBSTITUTE(SUBSTITUTE(TRIM(N11),"-","")," ","")),{"9MMAB","9MMAC","9MMAD","9MMAE","9MMAF","9MMAG","9MMAH"},0))),1,0) -> 3 | AT11: =IF(AND(AW11>0,AO11=0,AQ11=0,AR11=0,AS11=0,AU11=0),"READY",IF(AP11>0,"NOT READY – OVERDUE",IF(AQ11>0,"NOT READY – DISCREPANCY",IF(AU11>0,"NOT READY – INVALID ENTRY",IF(AR11>0,"NOT READY – DOCUMENTS",IF(AS11>0,"NOT READY – CLARIFICATION",IF(AND(AV11>0,SUMIFS(Checks!$AJ$5:$AJ$748,Checks!$B$5:$B$748,$A11,Checks!$H$5:$H$748,"Preparation")=SUMIFS(Checks!$AI$5:$AI$748,Checks!$B$5:$B$748,$A11,Checks!$H$5:$H$748,"Preparation")),"PREP DONE – AWAITING UPLIFT",IF(AV11=0,"NOT STARTED","IN PROGRESS")))))))) -> NOT READY – DOCUMENTS | AU11: =SUMIFS(Checks!$AM$5:$AM$748,Checks!$B$5:$B$748,$A11) -> 0 | AV11: =SUMIFS(Checks!$AJ$5:$AJ$748,Checks!$B$5:$B$748,$A11) -> 0 | AW11: =SUMIFS(Checks!$AI$5:$AI$748,Checks!$B$5:$B$748,$A11) -> 48 | AY11: =ROUND((IF(ISNUMBER(AX11),AX11,AA11-MIN($AB$10,$AB$18,$AB$26)/24)-UpliftWindowH/24)*1440,0)/1440 -> 46303.601 | AZ11: =ROUND((AY11+UpliftWindowH/24+MIN($AB$10,$AB$18,$AB$26)/24)*1440,0)/1440 -> 46304.417 | BA11: =IFERROR(1/(1/_xlfn.MINIFS(Checks!$AG$5:$AG$748,Checks!$B$5:$B$748,$A11,Checks!$H$5:$H$748,"Physical uplift",Checks!$P$5:$P$748,$G11)),"") | BB11: =SUMIFS(Checks!$BG$5:$BG$748,Checks!$B$5:$B$748,$A11) -> 0
A12: F08 | B12: 2 | C12: 8 | D12: 46305 | E12: SAT | F12: MH0752 | G12: KUL | H12: HAN | I12: 46305.399 | J12: 46305.51 | K12: EY | L12: B738MAX | M12: B737-8 (B7M8) | O12: 4A | P12: 2H 50M | Q12: Overnight HAN | R12: KUL/HAN/KUL | S12: ASEAN | T12: 1 Meal (Meal) | U12: KUL/HAN | V12: KUL | Z12: =IF(AND(INDEX(TZ_DSTS,MATCH(G12,TZ_STN,0))<>"",(I12-INDEX(TZ_STD,MATCH(G12,TZ_STN,0))/24)>=INDEX(TZ_DSTS,MATCH(G12,TZ_STN,0)),(I12-INDEX(TZ_STD,MATCH(G12,TZ_STN,0))/24)<INDEX(TZ_DSTE,MATCH(G12,TZ_STN,0))),INDEX(TZ_DST,MATCH(G12,TZ_STN,0)),INDEX(TZ_STD,MATCH(G12,TZ_STN,0))) -> 8 | AA12: =I12-Z12/24 -> 46305.066 | AB12: =(J12-(IF(AND(INDEX(TZ_DSTS,MATCH(H12,TZ_STN,0))<>"",(J12-INDEX(TZ_STD,MATCH(H12,TZ_STN,0))/24)>=INDEX(TZ_DSTS,MATCH(H12,TZ_STN,0)),(J12-INDEX(TZ_STD,MATCH(H12,TZ_STN,0))/24)<INDEX(TZ_DSTE,MATCH(H12,TZ_STN,0))),INDEX(TZ_DST,MATCH(H12,TZ_STN,0)),INDEX(TZ_STD,MATCH(H12,TZ_STN,0))))/24-AA12)*24 -> 3.6666667 | AC12: =AA12-7 -> 46298.066 | AD12: =AA12-1 -> 46304.066 | AE12: =AA12-0.5 -> 46304.566 | AF12: =AA12 -> 46305.066 | AG12: =AC12+(IF(AND(INDEX(TZ_DSTS,MATCH(V12,TZ_STN,0))<>"",AC12>=INDEX(TZ_DSTS,MATCH(V12,TZ_STN,0)),AC12<INDEX(TZ_DSTE,MATCH(V12,TZ_STN,0))),INDEX(TZ_DST,MATCH(V12,TZ_STN,0)),INDEX(TZ_STD,MATCH(V12,TZ_STN,0))))/24 -> 46298.399 | AH12: =AD12+(IF(AND(INDEX(TZ_DSTS,MATCH(V12,TZ_STN,0))<>"",AD12>=INDEX(TZ_DSTS,MATCH(V12,TZ_STN,0)),AD12<INDEX(TZ_DSTE,MATCH(V12,TZ_STN,0))),INDEX(TZ_DST,MATCH(V12,TZ_STN,0)),INDEX(TZ_STD,MATCH(V12,TZ_STN,0))))/24 -> 46304.399 | AI12: =AE12+(IF(AND(INDEX(TZ_DSTS,MATCH(V12,TZ_STN,0))<>"",AE12>=INDEX(TZ_DSTS,MATCH(V12,TZ_STN,0)),AE12<INDEX(TZ_DSTE,MATCH(V12,TZ_STN,0))),INDEX(TZ_DST,MATCH(V12,TZ_STN,0)),INDEX(TZ_STD,MATCH(V12,TZ_STN,0))))/24 -> 46304.899 | AJ12: =IFERROR(SUMIFS(Checks!$AJ$5:$AJ$748,Checks!$B$5:$B$748,$A12,Checks!$G$5:$G$748,"T-7D")/SUMIFS(Checks!$AI$5:$AI$748,Checks!$B$5:$B$748,$A12,Checks!$G$5:$G$748,"T-7D"),"n/a") -> 0 | AK12: =IFERROR(SUMIFS(Checks!$AJ$5:$AJ$748,Checks!$B$5:$B$748,$A12,Checks!$G$5:$G$748,"T-24H")/SUMIFS(Checks!$AI$5:$AI$748,Checks!$B$5:$B$748,$A12,Checks!$G$5:$G$748,"T-24H"),"n/a") -> 0 | AL12: =IFERROR(SUMIFS(Checks!$AJ$5:$AJ$748,Checks!$B$5:$B$748,$A12,Checks!$G$5:$G$748,"T-12H PREP")/SUMIFS(Checks!$AI$5:$AI$748,Checks!$B$5:$B$748,$A12,Checks!$G$5:$G$748,"T-12H PREP"),"n/a") -> 0 | AM12: =IFERROR(SUMIFS(Checks!$AJ$5:$AJ$748,Checks!$B$5:$B$748,$A12,Checks!$G$5:$G$748,"UPLIFT")/SUMIFS(Checks!$AI$5:$AI$748,Checks!$B$5:$B$748,$A12,Checks!$G$5:$G$748,"UPLIFT"),"n/a") -> 0 | AN12: =IFERROR(SUMIFS(Checks!$AJ$5:$AJ$748,Checks!$B$5:$B$748,$A12)/SUMIFS(Checks!$AI$5:$AI$748,Checks!$B$5:$B$748,$A12),"n/a") -> 0 | AO12: =AW12-AV12 -> 20 | AP12: =SUMIFS(Checks!$AK$5:$AK$748,Checks!$B$5:$B$748,$A12) -> 0 | AQ12: =SUMIFS(Checks!$AL$5:$AL$748,Checks!$B$5:$B$748,$A12) -> 0 | AR12: =Documents!P12 -> 2 | AS12: =SUMIFS(Checks!$AN$5:$AN$748,Checks!$B$5:$B$748,$A12,Checks!$H$5:$H$748,"Preparation")+IF(AND(TRIM(L12)="A350",ISNA(MATCH(UPPER(SUBSTITUTE(SUBSTITUTE(TRIM(N12),"-","")," ","")),{"9MMAB","9MMAC","9MMAD","9MMAE","9MMAF","9MMAG","9MMAH"},0))),1,0) -> 0 | AT12: =IF(AND(AW12>0,AO12=0,AQ12=0,AR12=0,AS12=0,AU12=0),"READY",IF(AP12>0,"NOT READY – OVERDUE",IF(AQ12>0,"NOT READY – DISCREPANCY",IF(AU12>0,"NOT READY – INVALID ENTRY",IF(AR12>0,"NOT READY – DOCUMENTS",IF(AS12>0,"NOT READY – CLARIFICATION",IF(AND(AV12>0,SUMIFS(Checks!$AJ$5:$AJ$748,Checks!$B$5:$B$748,$A12,Checks!$H$5:$H$748,"Preparation")=SUMIFS(Checks!$AI$5:$AI$748,Checks!$B$5:$B$748,$A12,Checks!$H$5:$H$748,"Preparation")),"PREP DONE – AWAITING UPLIFT",IF(AV12=0,"NOT STARTED","IN PROGRESS")))))))) -> NOT READY – DOCUMENTS | AU12: =SUMIFS(Checks!$AM$5:$AM$748,Checks!$B$5:$B$748,$A12) -> 0 | AV12: =SUMIFS(Checks!$AJ$5:$AJ$748,Checks!$B$5:$B$748,$A12) -> 0 | AW12: =SUMIFS(Checks!$AI$5:$AI$748,Checks!$B$5:$B$748,$A12) -> 20 | AX12: n/a | AY12: n/a | AZ12: n/a | BA12: =IFERROR(1/(1/_xlfn.MINIFS(Checks!$AG$5:$AG$748,Checks!$B$5:$B$748,$A12,Checks!$H$5:$H$748,"Physical uplift",Checks!$P$5:$P$748,$G12)),"") | BB12: =SUMIFS(Checks!$BG$5:$BG$748,Checks!$B$5:$B$748,$A12) -> 0
